Workbook
Name Nyears: Assumptions!$B$5
Name g_init: Assumptions!$B$6
Name g_term: Assumptions!$B$7
Name m_start: Assumptions!$B$9
Name m_target: Assumptions!$B$10
Name tax: Assumptions!$B$11
Name da_pct: Assumptions!$B$13
Name capex_pct: Assumptions!$B$14
Name nwc_pct: Assumptions!$B$15
Name rf: Assumptions!$B$17
Name erp: Assumptions!$B$18
Name beta: Assumptions!$B$19
Name kd_pre: Assumptions!$B$20
Name exit_mult: Assumptions!$B$22
Name Rev0: Assumptions!$B$24
Name NWC0: Assumptions!$B$25
Name TotalDebt: Assumptions!$B$26
Name NetDebt: Assumptions!$B$27
Name Shares: Assumptions!$B$28
Name CurPrice: Assumptions!$B$29
Name MktCap: Assumptions!$B$30
Name CostEquity: Assumptions!$B$32
Name AfterTaxKd: Assumptions!$B$33
Name WgtEquity: Assumptions!$B$34
Name WgtDebt: Assumptions!$B$35
Name WACC: Assumptions!$B$36

Sheet Assumptions
A1: Apple Inc. (AAPL) — DCF Assumptions & Inputs
A2: Generated 2026-08-07 | sector: general | horizon: 5 yrs | values in $ millions unless noted
A3: Item | B3: Value | C3: Unit | D3: Source / basis
A4: FORECAST
A5: Forecast horizon | B5: 5 | C5: yrs | D5: structural — regenerate the workbook to change the horizon
A6: Revenue growth — year 1 | B6: 0.052449453 | C6: %/yr | D6: blend of 3y (1.8%) & 5y (8.7%) historical revenue CAGR
A7: Revenue growth — terminal | B7: 0.025 | C7: %/yr | D7: assumption — near long-run nominal GDP growth
A8: PROFITABILITY
A9: EBIT margin — latest actual | B9: 0.319708 | C9: % | D9: latest FY operating margin (EBIT/Revenue)
A10: EBIT margin — steady state | B10: 0.30674711 | C10: % | D10: 5y avg operating margin (EBIT/Revenue)
A11: Effective tax rate | B11: 0.16785417 | C11: % | D11: 5y avg effective tax (tax expense / pre-tax income)
A12: CAPITAL INTENSITY (% of revenue)
A13: Depreciation & amortisation | B13: 0.029287294 | C13: %rev | D13: 5y avg D&A / revenue
A14: Capital expenditure | B14: 0.028152288 | C14: %rev | D14: 5y avg capex / revenue
A15: Net working capital | B15: -0.067826444 | C15: %rev | D15: 5y avg net working capital (AR + inventory - AP) / revenue
A16: COST OF CAPITAL (CAPM / WACC)
A17: Risk-free rate | B17: 0.042 | C17: % | D17: assumption — proxy for 10y US Treasury yield
A18: Equity risk premium | B18: 0.05 | C18: % | D18: assumption — long-run US equity risk premium (~5%)
A19: Equity beta | B19: 1.086 | C19: x | D19: yfinance equity beta
A20: Pre-tax cost of debt | B20: 0.027934405 | C20: % | D20: interest expense / total debt (historical avg)
A21: TERMINAL / EXIT
A22: Exit EV/EBITDA multiple | B22: 14 | C22: x | D22: assumption — mature-business EV/EBITDA exit multiple
A23: CAPITAL STRUCTURE & MARKET (snapshot — hard-coded)
A24: Base revenue (latest FY) | B24: 416161 | C24: $M | D24: AAPL FY2025 Revenue (10-K)
A25: Base net working capital | B25: -24365 | C25: $M | D25: AR + inventory - AP, latest FY (10-K)
A26: Total debt | B26: 98657 | C26: $M | D26: AAPL latest 10-K total debt
A27: Net debt | B27: 43960 | C27: $M | D27: total debt - cash - short-term investments (10-K)
A28: Shares outstanding | B28: 14594.18 | C28: M sh | D28: yfinance snapshot
A29: Current share price | B29: 312.095 | C29: $ | D29: yfinance snapshot 2026-08-07
A30: Market capitalisation | B30: 4554770.6 | C30: $M | D30: price x shares (snapshot)
A31: WACC BUILD (calculated)
A32: Cost of equity | B32: =rf+beta*erp | C32: % | D32: CAPM: rf + beta x ERP
A33: After-tax cost of debt | B33: =kd_pre*(1-tax) | C33: % | D33: kd x (1 - tax)
A34: Weight of equity | B34: =MktCap/(MktCap+TotalDebt) | C34: % | D34: E / (E + D)
A35: Weight of debt | B35: =TotalDebt/(MktCap+TotalDebt) | C35: % | D35: D / (E + D)
A36: WACC | B36: =WgtEquity*CostEquity+WgtDebt*AfterTaxKd | C36: % | D36: weighted average cost of capital
A38: LEGEND — model conventions
A39: Yellow fill, blue font | B39: Key assumption — intended for you to edit. Drives the whole model.
A40: Blue font (no fill) | B40: Hard-coded input: a reported SEC actual or a market snapshot.
A41: Black font | B41: Formula — calculated live by Excel. Do not overwrite.
...

Sheet DCF
A1: Discounted Cash Flow — unlevered FCFF ($M)
A2: Black = formula (recalculates). Edit assumptions on the Assumptions tab.
A3: ($ millions) | B3: Base FY0 | C3: Year 1 | D3: Year 2 | E3: Year 3 | F3: Year 4 | G3: Year 5
A4: Period (t) | B4: 0 | C4: 1 | D4: 2 | E4: 3 | F4: 4 | G4: 5
A5: Revenue growth | C5: =g_init+(g_term-g_init)*(C4-1)/(Nyears-1) | D5: =g_init+(g_term-g_init)*(D4-1)/(Nyears-1) | E5: =g_init+(g_term-g_init)*(E4-1)/(Nyears-1) | F5: =g_init+(g_term-g_init)*(F4-1)/(Nyears-1) | G5: =g_init+(g_term-g_init)*(G4-1)/(Nyears-1)
A6: Revenue | B6: =Rev0 | C6: =B6*(1+C5) | D6: =C6*(1+D5) | E6: =D6*(1+E5) | F6: =E6*(1+F5) | G6: =F6*(1+G5)
A7: EBIT margin | B7: =m_start | C7: =m_start+(m_target-m_start)*C4/Nyears | D7: =m_start+(m_target-m_start)*D4/Nyears | E7: =m_start+(m_target-m_start)*E4/Nyears | F7: =m_start+(m_target-m_start)*F4/Nyears | G7: =m_start+(m_target-m_start)*G4/Nyears
A8: EBIT | C8: =C6*C7 | D8: =D6*D7 | E8: =E6*E7 | F8: =F6*F7 | G8: =G6*G7
A9: NOPAT = EBIT x (1-tax) | C9: =C8*(1-tax) | D9: =D8*(1-tax) | E9: =E8*(1-tax) | F9: =F8*(1-tax) | G9: =G8*(1-tax)
A10: (+) D&A | C10: =C6*da_pct | D10: =D6*da_pct | E10: =E6*da_pct | F10: =F6*da_pct | G10: =G6*da_pct
A11: (-) Capex | C11: =C6*capex_pct | D11: =D6*capex_pct | E11: =E6*capex_pct | F11: =F6*capex_pct | G11: =G6*capex_pct
A12: Net working capital | B12: =NWC0 | C12: =C6*nwc_pct | D12: =D6*nwc_pct | E12: =E6*nwc_pct | F12: =F6*nwc_pct | G12: =G6*nwc_pct
A13: (-) Change in NWC | C13: =C12-B12 | D13: =D12-C12 | E13: =E12-D12 | F13: =F12-E12 | G13: =G12-F12
A14: Unlevered FCFF | C14: =C9+C10-C11-C13 | D14: =D9+D10-D11-D13 | E14: =E9+E10-E11-E13 | F14: =F9+F10-F11-F13 | G14: =G9+G10-G11-G13
A15: Discount factor | C15: =1/(1+WACC)^C4 | D15: =1/(1+WACC)^D4 | E15: =1/(1+WACC)^E4 | F15: =1/(1+WACC)^F4 | G15: =1/(1+WACC)^G4
A16: PV of FCFF | C16: =C14*C15 | D16: =D14*D15 | E16: =E14*E15 | F16: =F14*F15 | G16: =G14*G15
A18: VALUATION BRIDGE | B18: Gordon | C18: Exit mult.
A19: PV of explicit FCFF | B19: =SUM(C16:G16) | C19: =SUM(C16:G16)
A20: Terminal value (undiscounted) | B20: =G14*(1+g_term)/(WACC-g_term) | C20: =(G8+G10)*exit_mult
A21: PV of terminal value | B21: =B20*G15 | C21: =C20*G15
A22: Enterprise value | B22: =B19+B21 | C22: =C19+C21
A23: (-) Net debt | B23: =NetDebt | C23: =NetDebt
A24: Equity value | B24: =B22-B23 | C24: =C22-C23
A25: Implied share price | B25: =B24/Shares | C25: =C24/Shares
A26: Current share price | B26: =CurPrice | C26: =CurPrice
A27: Upside / (downside) | B27: =B25/CurPrice-1 | C27: =C25/CurPrice-1
A29: CROSS-CHECKS
A30: Terminal value % of EV (Gordon) | B30: =B21/B22
A31: Gordon TV implied EV/EBITDA | B31: =B20/(G8+G10)

Sheet Sensitivity
A1: Sensitivity — implied share price (Gordon): WACC x terminal growth
A2: Every cell is a live formula off the DCF FCFF stream — recalculates with the assumptions.
A3: WACC \ g
A4: =DCF!$B$25 | B4: =g_term+(-0.01) | C4: =g_term+(-0.005) | D4: =g_term+(0.0) | E4: =g_term+(0.005) | F4: =g_term+(0.01)
A5: =WACC+(-0.015) | B5: =((DCF!$C$14/(1+$A5)^1+DCF!$D$14/(1+$A5)^2+DCF!$E$14/(1+$A5)^3+DCF!$F$14/(1+$A5)^4+DCF!$G$14/(1+$A5)^5)+(DCF!$G$14*(1+B$4)/($A5-B$4)/(1+$A5)^5)-NetDebt)/Shares | C5: =((DCF!$C$14/(1+$A5)^1+DCF!$D$14/(1+$A5)^2+DCF!$E$14/(1+$A5)^3+DCF!$F$14/(1+$A5)^4+DCF!$G$14/(1+$A5)^5)+(DCF!$G$14*(1+C$4)/($A5-C$4)/(1+$A5)^5)-NetDebt)/Shares | D5: =((DCF!$C$14/(1+$A5)^1+DCF!$D$14/(1+$A5)^2+DCF!$E$14/(1+$A5)^3+DCF!$F$14/(1+$A5)^4+DCF!$G$14/(1+$A5)^5)+(DCF!$G$14*(1+D$4)/($A5-D$4)/(1+$A5)^5)-NetDebt)/Shares | E5: =((DCF!$C$14/(1+$A5)^1+DCF!$D$14/(1+$A5)^2+DCF!$E$14/(1+$A5)^3+DCF!$F$14/(1+$A5)^4+DCF!$G$14/(1+$A5)^5)+(DCF!$G$14*(1+E$4)/($A5-E$4)/(1+$A5)^5)-NetDebt)/Shares | F5: =((DCF!$C$14/(1+$A5)^1+DCF!$D$14/(1+$A5)^2+DCF!$E$14/(1+$A5)^3+DCF!$F$14/(1+$A5)^4+DCF!$G$14/(1+$A5)^5)+(DCF!$G$14*(1+F$4)/($A5-F$4)/(1+$A5)^5)-NetDebt)/Shares
A6: =WACC+(-0.01) | B6: =((DCF!$C$14/(1+$A6)^1+DCF!$D$14/(1+$A6)^2+DCF!$E$14/(1+$A6)^3+DCF!$F$14/(1+$A6)^4+DCF!$G$14/(1+$A6)^5)+(DCF!$G$14*(1+B$4)/($A6-B$4)/(1+$A6)^5)-NetDebt)/Shares | C6: =((DCF!$C$14/(1+$A6)^1+DCF!$D$14/(1+$A6)^2+DCF!$E$14/(1+$A6)^3+DCF!$F$14/(1+$A6)^4+DCF!$G$14/(1+$A6)^5)+(DCF!$G$14*(1+C$4)/($A6-C$4)/(1+$A6)^5)-NetDebt)/Shares | D6: =((DCF!$C$14/(1+$A6)^1+DCF!$D$14/(1+$A6)^2+DCF!$E$14/(1+$A6)^3+DCF!$F$14/(1+$A6)^4+DCF!$G$14/(1+$A6)^5)+(DCF!$G$14*(1+D$4)/($A6-D$4)/(1+$A6)^5)-NetDebt)/Shares | E6: =((DCF!$C$14/(1+$A6)^1+DCF!$D$14/(1+$A6)^2+DCF!$E$14/(1+$A6)^3+DCF!$F$14/(1+$A6)^4+DCF!$G$14/(1+$A6)^5)+(DCF!$G$14*(1+E$4)/($A6-E$4)/(1+$A6)^5)-NetDebt)/Shares | F6: =((DCF!$C$14/(1+$A6)^1+DCF!$D$14/(1+$A6)^2+DCF!$E$14/(1+$A6)^3+DCF!$F$14/(1+$A6)^4+DCF!$G$14/(1+$A6)^5)+(DCF!$G$14*(1+F$4)/($A6-F$4)/(1+$A6)^5)-NetDebt)/Shares
A7: =WACC+(-0.005) | B7: =((DCF!$C$14/(1+$A7)^1+DCF!$D$14/(1+$A7)^2+DCF!$E$14/(1+$A7)^3+DCF!$F$14/(1+$A7)^4+DCF!$G$14/(1+$A7)^5)+(DCF!$G$14*(1+B$4)/($A7-B$4)/(1+$A7)^5)-NetDebt)/Shares | C7: =((DCF!$C$14/(1+$A7)^1+DCF!$D$14/(1+$A7)^2+DCF!$E$14/(1+$A7)^3+DCF!$F$14/(1+$A7)^4+DCF!$G$14/(1+$A7)^5)+(DCF!$G$14*(1+C$4)/($A7-C$4)/(1+$A7)^5)-NetDebt)/Shares | D7: =((DCF!$C$14/(1+$A7)^1+DCF!$D$14/(1+$A7)^2+DCF!$E$14/(1+$A7)^3+DCF!$F$14/(1+$A7)^4+DCF!$G$14/(1+$A7)^5)+(DCF!$G$14*(1+D$4)/($A7-D$4)/(1+$A7)^5)-NetDebt)/Shares | E7: =((DCF!$C$14/(1+$A7)^1+DCF!$D$14/(1+$A7)^2+DCF!$E$14/(1+$A7)^3+DCF!$F$14/(1+$A7)^4+DCF!$G$14/(1+$A7)^5)+(DCF!$G$14*(1+E$4)/($A7-E$4)/(1+$A7)^5)-NetDebt)/Shares | F7: =((DCF!$C$14/(1+$A7)^1+DCF!$D$14/(1+$A7)^2+DCF!$E$14/(1+$A7)^3+DCF!$F$14/(1+$A7)^4+DCF!$G$14/(1+$A7)^5)+(DCF!$G$14*(1+F$4)/($A7-F$4)/(1+$A7)^5)-NetDebt)/Shares
A8: =WACC+(0.0) | B8: =((DCF!$C$14/(1+$A8)^1+DCF!$D$14/(1+$A8)^2+DCF!$E$14/(1+$A8)^3+DCF!$F$14/(1+$A8)^4+DCF!$G$14/(1+$A8)^5)+(DCF!$G$14*(1+B$4)/($A8-B$4)/(1+$A8)^5)-NetDebt)/Shares | C8: =((DCF!$C$14/(1+$A8)^1+DCF!$D$14/(1+$A8)^2+DCF!$E$14/(1+$A8)^3+DCF!$F$14/(1+$A8)^4+DCF!$G$14/(1+$A8)^5)+(DCF!$G$14*(1+C$4)/($A8-C$4)/(1+$A8)^5)-NetDebt)/Shares | D8: =((DCF!$C$14/(1+$A8)^1+DCF!$D$14/(1+$A8)^2+DCF!$E$14/(1+$A8)^3+DCF!$F$14/(1+$A8)^4+DCF!$G$14/(1+$A8)^5)+(DCF!$G$14*(1+D$4)/($A8-D$4)/(1+$A8)^5)-NetDebt)/Shares | E8: =((DCF!$C$14/(1+$A8)^1+DCF!$D$14/(1+$A8)^2+DCF!$E$14/(1+$A8)^3+DCF!$F$14/(1+$A8)^4+DCF!$G$14/(1+$A8)^5)+(DCF!$G$14*(1+E$4)/($A8-E$4)/(1+$A8)^5)-NetDebt)/Shares | F8: =((DCF!$C$14/(1+$A8)^1+DCF!$D$14/(1+$A8)^2+DCF!$E$14/(1+$A8)^3+DCF!$F$14/(1+$A8)^4+DCF!$G$14/(1+$A8)^5)+(DCF!$G$14*(1+F$4)/($A8-F$4)/(1+$A8)^5)-NetDebt)/Shares
A9: =WACC+(0.005) | B9: =((DCF!$C$14/(1+$A9)^1+DCF!$D$14/(1+$A9)^2+DCF!$E$14/(1+$A9)^3+DCF!$F$14/(1+$A9)^4+DCF!$G$14/(1+$A9)^5)+(DCF!$G$14*(1+B$4)/($A9-B$4)/(1+$A9)^5)-NetDebt)/Shares | C9: =((DCF!$C$14/(1+$A9)^1+DCF!$D$14/(1+$A9)^2+DCF!$E$14/(1+$A9)^3+DCF!$F$14/(1+$A9)^4+DCF!$G$14/(1+$A9)^5)+(DCF!$G$14*(1+C$4)/($A9-C$4)/(1+$A9)^5)-NetDebt)/Shares | D9: =((DCF!$C$14/(1+$A9)^1+DCF!$D$14/(1+$A9)^2+DCF!$E$14/(1+$A9)^3+DCF!$F$14/(1+$A9)^4+DCF!$G$14/(1+$A9)^5)+(DCF!$G$14*(1+D$4)/($A9-D$4)/(1+$A9)^5)-NetDebt)/Shares | E9: =((DCF!$C$14/(1+$A9)^1+DCF!$D$14/(1+$A9)^2+DCF!$E$14/(1+$A9)^3+DCF!$F$14/(1+$A9)^4+DCF!$G$14/(1+$A9)^5)+(DCF!$G$14*(1+E$4)/($A9-E$4)/(1+$A9)^5)-NetDebt)/Shares | F9: =((DCF!$C$14/(1+$A9)^1+DCF!$D$14/(1+$A9)^2+DCF!$E$14/(1+$A9)^3+DCF!$F$14/(1+$A9)^4+DCF!$G$14/(1+$A9)^5)+(DCF!$G$14*(1+F$4)/($A9-F$4)/(1+$A9)^5)-NetDebt)/Shares
A10: =WACC+(0.01) | B10: =((DCF!$C$14/(1+$A10)^1+DCF!$D$14/(1+$A10)^2+DCF!$E$14/(1+$A10)^3+DCF!$F$14/(1+$A10)^4+DCF!$G$14/(1+$A10)^5)+(DCF!$G$14*(1+B$4)/($A10-B$4)/(1+$A10)^5)-NetDebt)/Shares | C10: =((DCF!$C$14/(1+$A10)^1+DCF!$D$14/(1+$A10)^2+DCF!$E$14/(1+$A10)^3+DCF!$F$14/(1+$A10)^4+DCF!$G$14/(1+$A10)^5)+(DCF!$G$14*(1+C$4)/($A10-C$4)/(1+$A10)^5)-NetDebt)/Shares | D10: =((DCF!$C$14/(1+$A10)^1+DCF!$D$14/(1+$A10)^2+DCF!$E$14/(1+$A10)^3+DCF!$F$14/(1+$A10)^4+DCF!$G$14/(1+$A10)^5)+(DCF!$G$14*(1+D$4)/($A10-D$4)/(1+$A10)^5)-NetDebt)/Shares | E10: =((DCF!$C$14/(1+$A10)^1+DCF!$D$14/(1+$A10)^2+DCF!$E$14/(1+$A10)^3+DCF!$F$14/(1+$A10)^4+DCF!$G$14/(1+$A10)^5)+(DCF!$G$14*(1+E$4)/($A10-E$4)/(1+$A10)^5)-NetDebt)/Shares | F10: =((DCF!$C$14/(1+$A10)^1+DCF!$D$14/(1+$A10)^2+DCF!$E$14/(1+$A10)^3+DCF!$F$14/(1+$A10)^4+DCF!$G$14/(1+$A10)^5)+(DCF!$G$14*(1+F$4)/($A10-F$4)/(1+$A10)^5)-NetDebt)/Shares
A11: =WACC+(0.015) | B11: =((DCF!$C$14/(1+$A11)^1+DCF!$D$14/(1+$A11)^2+DCF!$E$14/(1+$A11)^3+DCF!$F$14/(1+$A11)^4+DCF!$G$14/(1+$A11)^5)+(DCF!$G$14*(1+B$4)/($A11-B$4)/(1+$A11)^5)-NetDebt)/Shares | C11: =((DCF!$C$14/(1+$A11)^1+DCF!$D$14/(1+$A11)^2+DCF!$E$14/(1+$A11)^3+DCF!$F$14/(1+$A11)^4+DCF!$G$14/(1+$A11)^5)+(DCF!$G$14*(1+C$4)/($A11-C$4)/(1+$A11)^5)-NetDebt)/Shares | D11: =((DCF!$C$14/(1+$A11)^1+DCF!$D$14/(1+$A11)^2+DCF!$E$14/(1+$A11)^3+DCF!$F$14/(1+$A11)^4+DCF!$G$14/(1+$A11)^5)+(DCF!$G$14*(1+D$4)/($A11-D$4)/(1+$A11)^5)-NetDebt)/Shares | E11: =((DCF!$C$14/(1+$A11)^1+DCF!$D$14/(1+$A11)^2+DCF!$E$14/(1+$A11)^3+DCF!$F$14/(1+$A11)^4+DCF!$G$14/(1+$A11)^5)+(DCF!$G$14*(1+E$4)/($A11-E$4)/(1+$A11)^5)-NetDebt)/Shares | F11: =((DCF!$C$14/(1+$A11)^1+DCF!$D$14/(1+$A11)^2+DCF!$E$14/(1+$A11)^3+DCF!$F$14/(1+$A11)^4+DCF!$G$14/(1+$A11)^5)+(DCF!$G$14*(1+F$4)/($A11-F$4)/(1+$A11)^5)-NetDebt)/Shares
A13: Center cell (boxed value on DCF) = base case. Blue headers recalc off WACC and terminal g on the Assumptions tab.

Sheet Historical
A1: AAPL — Historical financials (SEC EDGAR 10-K, $M)
A2: Reported actuals — hard-coded (blue) and cited; not part of the live formula chain.
A3: Line item ($M) | B3: FY2016 | C3: FY2017 | D3: FY2018 | E3: FY2019 | F3: FY2020 | G3: FY2021 | H3: FY2022 | I3: FY2023 | J3: FY2024 | K3: FY2025 | L3: Source
A4: Revenue | B4: 215639 | C4: 229234 | D4: 265595 | E4: 260174 | F4: 274515 | G4: 365817 | H4: 394328 | I4: 383285 | J4: 391035 | K4: 416161 | L4: XBRL: RevenueFromContractWithCustomerExcludingAssessedTax + Revenues + SalesRevenueNet
A5: COGS | B5: 131376 | C5: 141048 | D5: 163756 | E5: 161782 | F5: 169559 | G5: 212981 | H5: 223546 | I5: 214137 | J5: 210352 | K5: 220960 | L5: XBRL: CostOfGoodsAndServicesSold
A6: GrossProfit | B6: 84263 | C6: 88186 | D6: 101839 | E6: 98392 | F6: 104956 | G6: 152836 | H6: 170782 | I6: 169148 | J6: 180683 | K6: 195201 | L6: XBRL: derived: Revenue - COGS
A7: OperatingIncome | B7: 60024 | C7: 61344 | D7: 70898 | E7: 63930 | F7: 66288 | G7: 108949 | H7: 119437 | I7: 114301 | J7: 123216 | K7: 133050 | L7: XBRL: OperatingIncomeLoss
A8: PretaxIncome | B8: 61372 | C8: 64089 | D8: 72903 | E8: 65737 | F8: 67091 | G8: 109207 | H8: 119103 | I8: 113736 | J8: 123485 | K8: 132729 | L8: XBRL: IncomeLossFromContinuingOperationsBeforeIncomeTaxesExtraordinaryItemsNoncontrollingInterest + IncomeLossFromContinuingOperationsBeforeIncomeTaxesMinorityInterestAndIncomeLossFromEquityMethodInvestments
A9: IncomeTaxExpense | B9: 15685 | C9: 15738 | D9: 13372 | E9: 10481 | F9: 9680 | G9: 14527 | H9: 19300 | I9: 16741 | J9: 29749 | K9: 20719 | L9: XBRL: IncomeTaxExpenseBenefit
A10: NetIncome | B10: 45687 | C10: 48351 | D10: 59531 | E10: 55256 | F10: 57411 | G10: 94680 | H10: 99803 | I10: 96995 | J10: 93736 | K10: 112010 | L10: XBRL: NetIncomeLoss
A11: InterestExpense | B11: 1456 | C11: 2323 | D11: 3240 | E11: 3576 | F11: 2873 | G11: 2645 | H11: 2931 | I11: 3933 | J11: -- | K11: -- | L11: XBRL: InterestExpense
A12: DA | B12: 10505 | C12: 10157 | D12: 10903 | E12: 12547 | F12: 11056 | G12: 11284 | H12: 11104 | I12: 11519 | J12: 11445 | K12: 11698 | L12: XBRL: DepreciationDepletionAndAmortization + DepreciationAmortizationAndAccretionNet
A13: Capex | B13: 12734 | C13: 12451 | D13: 13313 | E13: 10495 | F13: 7309 | G13: 11085 | H13: 10708 | I13: 10959 | J13: 9447 | K13: 12715 | L13: XBRL: PaymentsToAcquirePropertyPlantAndEquipment + PaymentsToAcquireProductiveAssets
A14: CFO | B14: 66231 | C14: 64225 | D14: 77434 | E14: 69391 | F14: 80674 | G14: 104038 | H14: 122151 | I14: 110543 | J14: 118254 | K14: 111482 | L14: XBRL: NetCashProvidedByUsedInOperatingActivities + NetCashProvidedByUsedInOperatingActivitiesContinuingOperations
A15: Cash | B15: 20484 | C15: 20289 | D15: 25913 | E15: 48844 | F15: 38016 | G15: 34940 | H15: 23646 | I15: 29965 | J15: 29943 | K15: 35934 | L15: XBRL: CashAndCashEquivalentsAtCarryingValue
A16: ShortTermInvestments | B16: 46671 | C16: 53892 | D16: 40388 | E16: 51713 | F16: 52927 | G16: 27699 | H16: 24658 | I16: 31590 | J16: 35228 | K16: 18763 | L16: XBRL: MarketableSecuritiesCurrent + AvailableForSaleSecuritiesCurrent
A17: AccountsReceivable | B17: 15754 | C17: 17874 | D17: 23186 | E17: 22926 | F17: 16120 | G17: 26278 | H17: 28184 | I17: 29508 | J17: 33410 | K17: 39777 | L17: XBRL: AccountsReceivableNetCurrent
A18: Inventory | B18: 2132 | C18: 4855 | D18: 3956 | E18: 4106 | F18: 4061 | G18: 6580 | H18: 4946 | I18: 6331 | J18: 7286 | K18: 5718 | L18: XBRL: InventoryNet
A19: AccountsPayable | B19: 37294 | C19: 44242 | D19: 55888 | E19: 46236 | F19: 42296 | G19: 54763 | H19: 64115 | I19: 62611 | J19: 68960 | K19: 69860 | L19: XBRL: AccountsPayableCurrent
A20: TotalDebt | B20: 87032 | C20: 115680 | D20: 114483 | E20: 108047 | F20: 112436 | G20: 124719 | H20: 120069 | I20: 111088 | J20: 106629 | K20: 98657 | L20: XBRL: derived: LongTermDebt(noncurrent+current)+short-term
A21: NetDebt | B21: 19877 | C21: 41499 | D21: 48182 | E21: 7490 | F21: 21493 | G21: 62080 | H21: 71765 | I21: 49533 | J21: 41458 | K21: 43960 | L21: XBRL: derived: TotalDebt - Cash - ShortTermInvestments
A22: TotalAssets | B22: 321686 | C22: 375319 | D22: 365725 | E22: 338516 | F22: 323888 | G22: 351002 | H22: 352755 | I22: 352583 | J22: 364980 | K22: 359241 | L22: XBRL: Assets
A23: TotalEquity | B23: 128249 | C23: 134047 | D23: 107147 | E23: 90488 | F23: 65339 | G23: 63090 | H23: 50672 | I23: 62146 | J23: 56950 | K23: 73733 | L23: XBRL: StockholdersEquity
